<mujoco model="xarm6">
  <compiler angle="radian" autolimits="true"/>

  <option integrator="implicitfast"/>

  <!-- Meshes stored locally in simulation/data/xarm6/ -->
  <asset>
    <material name="white" rgba="1 1 1 1"/>
    <material name="gray" rgba="0.753 0.753 0.753 1"/>
    <material name="black" rgba="0.149 0.149 0.149 1"/>

    <!-- Arm links from visual/ -->
    <mesh file="visual/link_base.stl" name="link_base"/>
    <mesh file="visual/link1.stl" name="link1"/>
    <mesh file="visual/link2.stl" name="link2"/>
    <mesh file="visual/link3.stl" name="link3"/>
    <mesh file="visual/link4.stl" name="link4"/>
    <mesh file="visual/link5.stl" name="link5"/>
    <mesh file="visual/link6.stl" name="link6"/>

    <!-- Gripper parts from gripper/ -->
    <mesh file="gripper/base_link.stl" name="base_link"/>
    <mesh file="gripper/left_outer_knuckle.stl" name="left_outer_knuckle"/>
    <mesh file="gripper/left_finger.stl" name="left_finger"/>
    <mesh file="gripper/left_inner_knuckle.stl" name="left_inner_knuckle"/>
    <mesh file="gripper/right_outer_knuckle.stl" name="right_outer_knuckle"/>
    <mesh file="gripper/right_finger.stl" name="right_finger"/>
    <mesh file="gripper/right_inner_knuckle.stl" name="right_inner_knuckle"/>
  </asset>

  <default>
    <default class="xarm6">
      <geom type="mesh" material="white"/>
      <joint axis="0 0 1" armature="0.1" range="-6.28319 6.28319" frictionloss="1"/>
      <general biastype="affine" ctrlrange="-6.28319 6.28319"/>
      <default class="size1">
        <joint damping="10"/>
        <general gainprm="1500" biasprm="0 -1500 -150" forcerange="-50 50"/>
      </default>
      <default class="size2">
        <joint damping="5"/>
        <general gainprm="1000" biasprm="0 -1000 -100" forcerange="-32 32"/>
      </default>
      <default class="size3">
        <joint damping="2"/>
        <general gainprm="800" biasprm="0 -800 -80" forcerange="-20 20"/>
      </default>
      <default class="spring_link">
        <joint range="0 0.85" stiffness="0.05" springref="2.62" damping="0.00125"/>
      </default>
      <default class="driver">
        <joint range="0 0.85" armature="0.005" damping="0.1" solreflimit="0.005 1"/>
      </default>
      <default class="follower">
        <joint range="0 0.85" solreflimit="0.005 1"/>
      </default>
      <default class="visual">
        <geom type="mesh" contype="0" conaffinity="0" group="2"/>
      </default>
      <default class="collision">
        <geom type="mesh" group="3"/>
        <default class="pad_box1">
          <geom type="box" friction="0.7" solimp="0.95 0.99 0.001" solref="0.004 1" mass="0" priority="1" size="0.015 0.002 0.0095" rgba="0.0 0.1 0.7 1"/>
        </default>
        <default class="pad_box2">
          <geom type="box" friction="0.6" solimp="0.95 0.99 0.001" solref="0.004 1" mass="0" priority="1" size="0.015 0.002 0.0095" rgba="0.0 0.5 0.5 1"/>
        </default>
      </default>
      <site size="0.001" rgba="1 0 0 1" group="4"/>
    </default>
  </default>

  <!-- xarm6 kinematic chain based on xarm6_default_kinematics.yaml:
       joint1: xyz=(0, 0, 0.267), rpy=(0, 0, 0)
       joint2: xyz=(0, 0, 0), rpy=(-1.5708, 0, 0)
       joint3: xyz=(0.0535, -0.2845, 0), rpy=(0, 0, 0)  <- NO rotation!
       joint4: xyz=(0.0775, 0.3425, 0), rpy=(-1.5708, 0, 0)
       joint5: xyz=(0, 0, 0), rpy=(1.5708, 0, 0)
       joint6: xyz=(0.076, 0.097, 0), rpy=(-1.5708, 0, 0)
  -->
  <worldbody>
    <body name="link_base" pos="0 0 .12" childclass="xarm6">
      <inertial pos="0 0 0.09103" mass="2.7"
        diaginertia="0.00494875 0.00494174 0.002219"/>
      <geom mesh="link_base"/>
      <!-- joint1: xyz=(0, 0, 0.267), rpy=(0, 0, 0) -->
      <body name="link1" pos="0 0 0.267">
        <inertial pos="-0.0002 0.02905 -0.01233" quat="0.978953 -0.202769 -0.00441617 -0.0227264" mass="2.382"
          diaginertia="0.00569127 0.00533384 0.00293865"/>
        <joint name="joint1" class="size1"/>
        <geom mesh="link1"/>
        <!-- joint2: xyz=(0, 0, 0), rpy=(-1.5708, 0, 0) -> quat for -90deg X rotation -->
        <body name="link2" quat="0.7071068 -0.7071068 0 0">
          <inertial pos="0.00022 -0.12856 0.01735" quat="0.50198 0.86483 -0.00778841 0.00483285" mass="1.869"
            diaginertia="0.00959898 0.00937717 0.00201315"/>
          <joint name="joint2" range="-2.059 2.0944" class="size1"/>
          <geom mesh="link2"/>
          <!-- joint3: xyz=(0.0535, -0.2845, 0), rpy=(0, 0, 0) -> NO rotation, just position -->
          <body name="link3" pos="0.0535 -0.2845 0">
            <inertial pos="0.0466 -0.02463 -0.00768" quat="0.913819 0.289775 0.281481 -0.0416455" mass="1.6383"
              diaginertia="0.00351721 0.00294089 0.00195868"/>
            <joint name="joint3" range="-3.927 0.19198" class="size2"/>
            <geom mesh="link3"/>
            <!-- joint4: xyz=(0.0775, 0.3425, 0), rpy=(-1.5708, 0, 0) -> quat for -90deg X -->
            <body name="link4" pos="0.0775 0.3425 0" quat="0.7071068 -0.7071068 0 0">
              <inertial pos="0.07047 -0.11575 0.012" quat="0.422108 0.852026 -0.126025 0.282832" mass="1.7269"
                diaginertia="0.00657137 0.00647948 0.00186763"/>
              <joint name="joint4" class="size2"/>
              <geom mesh="link4"/>
              <!-- joint5: xyz=(0, 0, 0), rpy=(1.5708, 0, 0) -> quat for +90deg X -->
              <body name="link5" quat="0.7071068 0.7071068 0 0">
                <inertial pos="-0.00032 0.01604 -0.026" quat="0.999311 -0.0304457 0.000577067 0.0212082" mass="1.3203"
                  diaginertia="0.00534729 0.00499076 0.0013489"/>
                <joint name="joint5" range="-1.69297 3.14159" class="size2"/>
                <geom mesh="link5"/>
                <!-- joint6: xyz=(0.076, 0.097, 0), rpy=(-1.5708, 0, 0) -> quat for -90deg X -->
                <body name="link6" pos="0.076 0.097 0" quat="0.7071068 -0.7071068 0 0">
                  <inertial pos="0 -0.00677 -0.01098" quat="0.487612 0.512088 -0.512088 0.487612" mass="0.17"
                    diaginertia="0.000132176 9.3e-05 5.85236e-05"/>
                  <joint name="joint6" class="size3"/>
                  <geom material="gray" mesh="link6"/>
                  <body name="xarm_gripper_base_link" quat="0 0 0 1">
                    <inertial pos="-0.00065489 -0.0018497 0.048028" quat="0.997403 -0.0717512 -0.0061836 0.000477479"
                      mass="0.54156" diaginertia="0.000471093 0.000332307 0.000254799"/>
                    <geom mesh="base_link"/>
                    <body name="left_outer_knuckle" pos="0 0.035 0.059098">
                      <inertial pos="0 0.021559 0.015181" quat="0.47789 0.87842 0 0" mass="0.033618"
                        diaginertia="1.9111e-05 1.79089e-05 1.90167e-06"/>
                      <joint name="left_driver_joint" axis="1 0 0" class="driver"/>
                      <geom material="black" mesh="left_outer_knuckle"/>
                      <body name="left_finger" pos="0 0.035465 0.042039">
                        <inertial pos="0 -0.016413 0.029258" quat="0.697634 0.115353 -0.115353 0.697634"
                          mass="0.048304" diaginertia="1.88037e-05 1.7493e-05 3.56792e-06"/>
                        <joint name="left_finger_joint" axis="-1 0 0" class="follower"/>
                        <geom class="visual" material="black" mesh="left_finger"/>
                        <geom class="pad_box1" name="left_finger_pad_1" pos="0 -0.024003 0.032"/>
                        <geom class="pad_box2" name="left_finger_pad_2" pos="0 -0.024003 0.050"/>
                      </body>
                    </body>
                    <body name="left_inner_knuckle" pos="0 0.02 0.074098">
                      <inertial pos="1.86601e-06 0.0220468 0.0261335" quat="0.664139 -0.242732 0.242713 0.664146"
                        mass="0.0230126" diaginertia="8.34216e-06 6.0949e-06 2.75601e-06"/>
                      <joint name="left_inner_knuckle_joint" axis="1 0 0" class="spring_link"/>
                      <geom material="black" mesh="left_inner_knuckle"/>
                    </body>
                    <body name="right_outer_knuckle" pos="0 -0.035 0.059098">
                      <inertial pos="0 -0.021559 0.015181" quat="0.87842 0.47789 0 0" mass="0.033618"
                        diaginertia="1.9111e-05 1.79089e-05 1.90167e-06"/>
                      <joint name="right_driver_joint" axis="-1 0 0" class="driver"/>
                      <geom material="black" mesh="right_outer_knuckle"/>
                      <body name="right_finger" pos="0 -0.035465 0.042039">
                        <inertial pos="0 0.016413 0.029258" quat="0.697634 -0.115356 0.115356 0.697634"
                          mass="0.048304" diaginertia="1.88038e-05 1.7493e-05 3.56779e-06"/>
                        <joint name="right_finger_joint" axis="1 0 0" class="follower"/>
                        <geom class="visual" material="black" mesh="right_finger"/>
                        <geom class="pad_box1" name="right_finger_pad_1" pos="0 0.024003 0.032"/>
                        <geom class="pad_box2" name="right_finger_pad_2" pos="0 0.024003 0.050"/>
                      </body>
                    </body>
                    <body name="right_inner_knuckle" pos="0 -0.02 0.074098">
                      <inertial pos="1.866e-06 -0.022047 0.026133" quat="0.66415 0.242702 -0.242721 0.664144"
                        mass="0.023013" diaginertia="8.34209e-06 6.0949e-06 2.75601e-06"/>
                      <joint name="right_inner_knuckle_joint" axis="-1 0 0" class="spring_link"/>
                      <geom material="black" mesh="right_inner_knuckle"/>
                    </body>
                    <site name="link_tcp" pos="0 0 .172"/>
                  </body>
                </body>
              </body>
            </body>
          </body>
        </body>
      </body>
    </body>
  </worldbody>

  <contact>
    <exclude body1="right_inner_knuckle" body2="right_outer_knuckle"/>
    <exclude body1="right_inner_knuckle" body2="right_finger"/>
    <exclude body1="left_inner_knuckle" body2="left_outer_knuckle"/>
    <exclude body1="left_inner_knuckle" body2="left_finger"/>
  </contact>

  <tendon>
    <fixed name="split">
      <joint joint="right_driver_joint" coef="0.5"/>
      <joint joint="left_driver_joint" coef="0.5"/>
    </fixed>
  </tendon>

  <equality>
    <connect anchor="0 0.015 0.015" body1="right_finger" body2="right_inner_knuckle" solref="0.005 1"/>
    <connect anchor="0 -0.015 0.015" body1="left_finger" body2="left_inner_knuckle" solref="0.005 1"/>
    <joint joint1="left_driver_joint" joint2="right_driver_joint" polycoef="0 1 0 0 0" solref="0.005 1"/>
  </equality>

  <actuator>
    <general name="act1" joint="joint1" class="size1"/>
    <general name="act2" joint="joint2" class="size1" ctrlrange="-2.059 2.0944"/>
    <general name="act3" joint="joint3" class="size2" ctrlrange="-3.927 0.19198"/>
    <general name="act4" joint="joint4" class="size2"/>
    <general name="act5" joint="joint5" class="size2" ctrlrange="-1.69297 3.14159"/>
    <general name="act6" joint="joint6" class="size3"/>
    <general name="gripper" tendon="split" forcerange="-50 50" ctrlrange="0 255" biastype="affine" gainprm="0.333"
      biasprm="0 -100 -10"/>
  </actuator>

  <keyframe>
    <key name="home" qpos="0 0 0 0 0 0 0 0 0 0 0 0" ctrl="0 0 0 0 0 0 0"/>
  </keyframe>
</mujoco>
